Workbook

Sheet 요약
A1: M1 디지털트윈·Maxwell 3D용 전체 데이터 시트 — 현대 SSEN HLP-2.2/4, 스큐 설계 확정판 (v3)
A2: AI Hub L-SF-04 (2.2 kW 4P 1760 rpm 4.7 A, 6206/6206) 와 명판 3값 일치 → 같은 모터로 취급
A4: 구분 | B4: 내용 | C4: 값 (라이브 링크) | D4: 비고
A5: 확정 설계 | B5: 고정자 / 로터 슬롯 수 | C5: ="36 / "&'설계값(라이브)'!$C$48 -> 36 / 28 | D5: 스큐 전제 최적 조합. 후보 {26,28,44,46} 중 28 — 「로터슬롯 선정근거」
A6: 확정 설계 | B6: 로터 스큐 | C6: ='설계값(라이브)'!$C$49&" 고정자 슬롯피치 = "&TEXT('설계값(라이브)'!$C$156,"0.0")&"° mech / "&TEXT('설계값(라이브)'!$C$157,"0")&"° elec" -> 1 고정자 슬롯피치 = 10.0° mech / 20° elec | D6: 바 기울기 ≈ 3.6°
A7: 확정 설계 | B7: 권선 | C7: ="2층 중권, 피치 "&'설계값(라이브)'!$C$51&"/9, a="&'설계값(라이브)'!$C$52&", 코일당 "&'설계값(라이브)'!$C$67&" turn, "&'설계값(라이브)'!$C$53&"×Ø"&TEXT('설계값(라이브)'!$C$54,"0.00") -> 2층 중권, 피치 8/9, a=1, 코일당 15 turn, 2×Ø0.90 | D7: N_ph =
A8: 확정 설계 | B8: 상당 직렬 턴수 | C8: ='설계값(라이브)'!$C$68 -> 180 | D8: ITSC 비율 정의의 분모
A9: 확정 설계 | B9: 코어 | C9: ="D_so "&'설계값(라이브)'!$C$35&" / D_si "&'설계값(라이브)'!$C$37&" / L "&'설계값(라이브)'!$C$41&" / g "&'설계값(라이브)'!$C$39&" mm" -> D_so 155 / D_si 98 / L 135 / g 0.3 mm
A10: 검산 | B10: 효율 (계산 vs 카탈로그 89.5 %) | C10: ='설계값(라이브)'!$C$120 -> 0.89428246 | D10: ±0.3 %p 이내 정합
A11: 검산 | B11: 로터 관성 (치수 계산 vs 카탈로그 0.008) | C11: ='설계값(라이브)'!$C$183 -> 0.0085964763 | D11: ±20 % 이내면 L 정합
A12: 검산 | B12: 자화 전류 (계산 vs 무효전류 2.90 A) | C12: ='설계값(라이브)'!$C$176 -> 2.6225479 | D12: 이하이면 역률 정합
A13: 검산 | B13: 바 단면 정합 (슬롯 − 요구) | C13: ='설계값(라이브)'!$C$145 -> 0.0015860451 | D13: ±3 %
A14: MCSA | B14: 로터 슬롯 고조파 (정격 슬립) | C14: =TEXT('MCSA·진동 주파수'!C6,"0")&" / "&TEXT('MCSA·진동 주파수'!C7,"0")&" Hz" -> 761 / 881 Hz | D14: Q_r 판별용
A15: 등급 집계 | B15: 카탈로그 직접값 | C15: =COUNTIF('설계값(라이브)'!$E$5:$E$300,"카탈로그") -> 16
A16: 등급 집계 | B16: 계산 (수식) | C16: =COUNTIF('설계값(라이브)'!$E$5:$E$300,"계산") -> 116
A17: 등급 집계 | B17: 표준값 (규격·핸드북) | C17: =COUNTIF('설계값(라이브)'!$E$5:$E$300,"표준") -> 24
A18: 등급 집계 | B18: 설계선택 (성능 정합) | C18: =COUNTIF('설계값(라이브)'!$E$5:$E$300,"설계선택") -> 15
A19: 등급 집계 | B19: 현장 확인 필요 | C19: =COUNTIF('설계값(라이브)'!$E$5:$E$300,"현장확인") -> 6 | D19: Q_r·스큐·결선·턴수·병렬회로·베어링
A21: 시트 구성: 설계값(라이브) → RMxprt 입력표 / ITSC 케이스 / MCSA·진동 주파수 가 자동 연동. 카탈로그 직접값·로터슬롯 선정근거·현장확인 체크리스트는 정적.
A23: Maxwell 3D 구현 충족 여부 (이 시트만으로 되는가)
A24: 필요 블록 | B24: 충족 | C24: 시트 | D24: 비고
A25: RMxprt 모델 생성 입력 (지오메트리·슬롯·권선·로터·스큐) | B25: ✓ | C25: RMxprt 입력표 | D25: RMxprt → Create Maxwell Design (3D) 로 자동 생성
A26: 권선 배치·결함 코일 위치·분할 비율 | B26: ✓ | C26: 권선 배치표, ITSC 케이스 | D26: Coil_1 분할 → FaultLoop
A27: 케이스별 속도(슬립)·시간·메시·경계·솔버 설정 | B27: ✓ | C27: 해석 설정(3D)
A28: 외부 회로 넷리스트 (전원·결함 가지·저항) | B28: ✓ | C28: 출력 변수·회로 | D28: Circuit Editor 에서 구성
A29: 출력 변수·내보내기 계약 | B29: ✓ | C29: 출력 변수·회로 | D29: PyAEDT 스크립트는 별도
A30: 전기강판 B-H 곡선·코어손 계수 | B30: △ | C30: 해석 설정(3D) 재질 | D30: ★ 곡선 데이터 미보유 — Maxwell 라이브러리 M400-50A 또는 강판사 데이터시트 필요
A31: 실측 확정값 (Q_r·스큐·결선·턴수) | B31: △ | C31: 현장확인 체크리스트 | D31: 가정값으로 구현 가능, 확인 후 교체

Sheet 설계값(라이브)
A1: M1 = 현대 SSEN HLP-2.2/4 (100L, 4P) — 스큐 설계 확정판 설계값 (라이브 계산 체인)
A2: 셀 색: 연두 = 카탈로그 직접값 / 노랑 = 표준·설계선택 입력(수정 가능, 파란 글씨) / 흰색 = 수식 계산 / 주황 = 현장 확인 필요. Q_r·L·스큐를 바꾸면 아래 전부 재계산됨.
A4: 항목 | B4: 기호 | C4: 값 | D4: 단위 | E4: 출처등급 | F4: 식 / 근거
A5: 1. 카탈로그 입력 (현대 SSEN 카탈로그 HLP-2.2/4, 380 V 행)
A6: 정격 출력 | B6: P | C6: 2200 | D6: W | E6: 카탈로그
A7: 선간 전압 | B7: V_L | C7: 380 | D7: V | E7: 카탈로그
A8: 정격 전류 (380 V) | B8: I_n | C8: 4.73 | D8: A | E8: 카탈로그
A9: 효율 (100 % 부하) | B9: η | C9: 0.895 | D9: - | E9: 카탈로그
A10: 역률 | B10: cosφ | C10: 0.79 | D10: - | E10: 카탈로그
A11: 주파수 | B11: f | C11: 60 | D11: Hz | E11: 카탈로그
A12: 극수 | B12: 2p | C12: 4 | D12: - | E12: 카탈로그
A13: 정격 회전수 | B13: n_n | C13: 1760 | D13: rpm | E13: 카탈로그
A14: 기동 토크비 | B14: T_st/T_n | C14: 2.1 | D14: - | E14: 카탈로그 | F14: 210 %
A15: 최대 토크비 | B15: T_max/T_n | C15: 2.5 | D15: - | E15: 카탈로그 | F15: 250 %
A16: 기동 전류비 | B16: I_st/I_n | C16: 6.5 | D16: - | E16: 카탈로그 | F16: 650 %
A17: Rotor GD² (카탈로그 열 이름) | B17: GD² | C17: 0.008 | D17: kg·m² | E17: 카탈로그 | F17: §9 검산: 로터 치수에서 계산한 J와 비교하면 이 값은 사실상 J
A18: 중량 | B18: m | C18: 41 | D18: kg | E18: 카탈로그
A19: 베어링 DE / NDE | B19: - | C19: 6206ZZC3 / 6206ZZC3 | D19: - | E19: 카탈로그
A20: 절연 / 온도상승 / SF | B20: - | C20: F / B / 1.15 | D20: - | E20: 카탈로그
A21: 허용 진동 | B21: - | C21: 2.8 | D21: mm/s | E21: 카탈로그
A22: 2. 기본 계산 (가정 없음)
A23: 극쌍수 | B23: p | C23: =$C$12/2 -> 2 | D23: - | E23: 계산
A24: 동기속도 | B24: n_s | C24: =120*$C$11/$C$12 -> 1800 | D24: rpm | E24: 계산
A25: 정격 슬립 | B25: s | C25: =($C$24-$C$13)/$C$24 -> 0.022222222 | D25: - | E25: 계산
A26: 상전압 (Y, 220/380 겸용형 380 V 기준) | B26: V_ph | C26: =$C$7/SQRT(3) -> 219.3931 | D26: V | E26: 계산 | F26: 380 V 전용형 결선은 명판 확인
A27: 입력 전력 | B27: P_in | C27: =$C$6/$C$9 -> 2458.1006 | D27: W | E27: 계산
A28: 총손실 (카탈로그) | B28: ΣP_loss | C28: =$C$27-$C$6 -> 258.10056 | D28: W | E28: 계산
A29: 정격 토크 | B29: T_n | C29: =9549*$C$6/1000/$C$13 -> 11.93625 | D29: N·m | E29: 계산 | F29: 카탈로그 1.22 kg·m = 11.96 N·m
A30: 무효 전류 | B30: I·sinφ | C30: =$C$8*SQRT(1-$C$10^2) -> 2.8999954 | D30: A | E30: 계산
A31: 기동 전류 | B31: I_st | C31: =$C$16*$C$8 -> 30.745 | D31: A | E31: 계산
A32: 기동 임피던스 (Y 기준) | B32: Z_sc | C32: =$C$26/$C$31 -> 7.1358953 | D32: Ω | E32: 계산
A33: 로터 관성 (GD² 열을 J로 해석) | B33: J | C33: =$C$17 -> 0.008 | D33: kg·m² | E33: 계산 | F33: §9 치수 검산과 일치 (GD²/4 = 0.002 는 적층 29 mm 가 되어 비현실)
A34: 3. 코어·공극 — 표준값 + 계산
A35: 고정자 외경 | B35: D_so | C35: 155 | D35: mm | E35: 표준 | F35: IEC 프레임 100 TEFC 주철 코어 외경 표준 (≈1.55·H)
A36: 내외경비 | B36: D_si/D_so | C36: 0.63 | D36: - | E36: 표준 | F36: Boldea & Nasar Table 15.2, 2p=4: 0.61–0.66
A37: 고정자 내경 | B37: D_si | C37: =ROUND($C$35*$C$36,0) -> 98 | D37: mm | E37: 계산
A38: 공극 (Pyrhönen 식) | B38: δ | C38: =0.18+0.006*$C$6^0.4 -> 0.31035279 | D38: mm | E38: 계산 | F38: Pyrhönen Eq.(6.24): 0.18+0.006·P^0.4
A39: 공극 (채택) | B39: g | C39: 0.3 | D39: mm | E39: 표준 | F39: 0.05 단위 가공 표준으로 반올림
A40: 로터 외경 | B40: D_ro | C40: =$C$37-2*$C$39 -> 97.4 | D40: mm | E40: 계산
A41: 적층 길이 | B41: L | C41: 135 | D41: mm | E41: 설계선택 | F41: 효율 89.5 % 정합 스윕(더블체크 §9) 최초 도달값. §9 관성 검산으로 확인
...

Sheet 카탈로그 직접값
A1: 현대 SSEN HLP-2.2/4 (100L) — 카탈로그에서 직접 읽은 값
A3: 항목 | B3: 값 | C3: 단위 | D3: 비고
A4: 형식 / 카탈로그 번호 | B4: HLP-2.2/4 / P2P2TC276 (380 V) | C4: - | D4: 220/380 V: P2P2TC226, 440 V: P2P2TC216
A5: 정격 출력 / 극수 / 프레임 | B5: 2.2 kW / 4P / 100L | C5: -
A6: 정격 회전수 | B6: 1760 | C6: rpm
A7: 정격 전압 | B7: 220/380, 380, 440 | C7: V | D7: 3상 60 Hz
A8: 정격 전류 220 / 380 / 440 V | B8: 8.17 / 4.73 / 4.08 | C8: A
A9: 효율 100 / 75 / 50 % | B9: 89.5 / 89.4 / 88.0 | C9: % | D9: KS C 4202 프리미엄
A10: 역률 | B10: 0.79 | C10: -
A11: 기동 전류 / 기동 토크 / 최대 토크 | B11: 650 % / 210 % / 250 % | C11: -
A12: 정격 토크 | B12: 1.22 | C12: kg·m | D12: ≒ 11.96 N·m
A13: Rotor GD² / 중량 / 소음 | B13: 0.0080 / 41 / 60 | C13: kg·m² / kg / dB(A)
A14: 베어링 DE / NDE | B14: 6206ZZC3 / 6206ZZC3 | C14: -
A15: 절연 / 온도상승 / SF | B15: F / B / 1.15 | C15: -
A16: 외함 / 냉각 / 보호 | B16: TEFC / IC411 / IP55 | C16: -
A17: 회전자 / 권선 | B17: Al 다이캐스팅 / 구리 에나멜선 | C17: -
A18: 설계 / 효율기준 | B18: NEMA B · IEC N / IE3 | C18: -
A19: 허용 진동 | B19: 2.8 | C19: mm/s RMS
A20: 치수 H / A / B1 / C | B20: 100 / 160 / 140 / 63 | C20: mm
A21: 치수 HC / HD / L | B21: 211 / 247 / 370 | C21: mm
A22: 축단 D / E / F / GE, 키 | B22: 28 / 60 / 8 / 4, 8×7×45 | C22: mm | D22: j6
A23: 플랜지 FF215 M / N / P | B23: 215 / 180 / 250 | C23: mm

Sheet 로터슬롯 선정근거
A1: 로터 슬롯 수 선정 — Q_s = 36, 4극, 스큐 1 고정자 슬롯피치 전제
A2: 기준: K1 잠김 c·Q_r=g·Q_s / K2 동기토크 |p±c·Q_r| = 고정자 고조파 극쌍수 (같은 방향→정지, 반대→n=±120f/(cQ_r)) / K3 힘파 차수 r=|Q_s−Q_r|, |Q_s−Q_r±2p| / K4 짝수·0.7~1.3Q_s / K5 RSH 측정 대역
A4: Q_r | B4: 힘파 차수 r (1차) | C4: r_min | D4: 동기 토크 | E4: 스큐 없이 | F4: 스큐 1슬롯 | G4: RSH @s=2.2 % (Hz) | H4: 판정
A5: 24 | B5: 8, 12, 16 | C5: 8 | D5: 정지 시 13차 (6p 배수) | E5: ✗ | F5: ✗ | G5: 644 / 764 | H5: 제외
A6: 26 | B6: 6, 10, 14 | C6: 6 | D6: 25차·c=2 (무시) | E6: ✓ 최적 | F6: ✓ | G6: 703 / 823 | H6: 대안 (스큐 없는 설계면 1순위)
A7: 28 | B7: 4, 8, 12 | C7: 4 | D7: 13차 → +257 rpm, 미약 (k_w13 0.14 × k_sk13 0.34) | E7: △ (r=4) | F7: ✓ r=4 힘파 95 % 감쇠 | G7: 761 / 881 | H7: ★ 확정 — 스큐 전제, 양산 관행
A8: 30 | B8: 2, 6, 10 | C8: 2 | D8: - | E8: ✗ r=2 | F8: ✗ | G8: 820 / 940 | H8: 제외
A9: 32 | B9: 0, 4, 8 | C9: 0 | D9: 슬롯 고조파 → −225 rpm | E9: ✗ r=0 | F9: △ 일부 양산 시리즈 사용 | G9: 879 / 999 | H9: 제외 (측정 후보에는 포함)
A10: 34 | B10: 2, 6 | C10: 2 | D10: 슬롯 고조파 역방향 | E10: ✗ | F10: ✗ | G10: 938 / 1058 | H10: 제외
A11: 36 | B11: 0, 4 | C11: 0 | D11: 잠김 | E11: ✗ | F11: ✗ | G11: 996 / 1116 | H11: 제외
A12: 38 | B12: 2, 6 | C12: 2 | D12: 2차 슬롯 → +95 rpm | E12: ✗ | F12: ✗ | G12: 1055 / 1175 | H12: 제외
A13: 40 | B13: 0, 4, 8 | C13: 0 | D13: 슬롯 고조파 → +180 rpm 기동 중 | E13: ✗ | F13: ✗ | G13: 1114 / 1234 | H13: 제외 (최악)
A14: 42 | B14: 2, 6, 10 | C14: 2 | D14: - | E14: ✗ | F14: ✗ | G14: 1172 / 1292 | H14: 제외
A15: 44 | B15: 4, 8, 12 | C15: 4 | D15: 23차 → −164 rpm, 미약 | E15: △ | F15: ✓ | G15: 1231 / 1351 | H15: 대안 (Q_r>Q_s, 2 kHz 전류로 RSH 확인 불가)
A16: 46 | B16: 6, 10, 14 | C16: 6 | D16: 없음 | E16: ✓ | F16: ✓ | G16: 1290 / 1410 | H16: 대안 (바 가늘어짐, RSH 확인 불가)
A18: 스큐 1슬롯(20° 전기각)에서 고정자 슬롯 고조파 17·19차의 스큐 계수 0.059 / 0.052 → 28의 r=4 힘파와 32·40의 슬롯 고조파 동기토크가 모두 ~95 % 감쇠. 따라서 스큐 전제에서는 26과 28이 동급이고, 양산 관행·바 단면·RSH 관측성(<1 kHz)을 고려해 28 확정.
A19: 26 vs 28 성능 차이: 바 면적 7 % → 바 형상 보정으로 흡수. ITSC I₂/I₁ 에는 영향 없음.
A20: 실제 모터 값은 AI Hub L-SF-04 전류 스펙트럼의 RSH 쌍(120 Hz 간격)으로 판별: 703/823 → 26, 761/881 → 28, 879/999 → 32. 1 kHz 아래에 쌍이 없으면 44 이상 또는 안티에일리어싱 필터.

Sheet RMxprt 입력표
A1: RMxprt (Three-Phase Induction Motor) 입력 필드 매핑 — 값은 설계값(라이브) 링크
A3: RMxprt 패널 | B3: 필드 | C3: 값 | D3: 단위 | E3: 비고
A4: General | B4: Rated Output Power | C4: ='설계값(라이브)'!$C$6 -> 2200 | D4: W
A5: General | B5: Rated Voltage (line) | C5: ='설계값(라이브)'!$C$7 -> 380 | D5: V
A6: General | B6: Number of Poles | C6: ='설계값(라이브)'!$C$12 -> 4 | D6: -
A7: General | B7: Frequency | C7: ='설계값(라이브)'!$C$11 -> 60 | D7: Hz
A8: General | B8: Rated Speed (목표) | C8: ='설계값(라이브)'!$C$13 -> 1760 | D8: rpm | E8: 결과 검증
A9: General | B9: Winding Connection | C9: Wye (220/380 겸용형 380 V) | D9: - | E9: 380 V 전용형은 명판
A10: Stator | B10: Outer Diameter | C10: ='설계값(라이브)'!$C$35 -> 155 | D10: mm
A11: Stator | B11: Inner Diameter | C11: ='설계값(라이브)'!$C$37 -> 98 | D11: mm
A12: Stator | B12: Length | C12: ='설계값(라이브)'!$C$41 -> 135 | D12: mm
A13: Stator | B13: Stacking Factor | C13: ='설계값(라이브)'!$C$42 -> 0.96 | D13: -
A14: Stator | B14: Steel Type | C14: ='설계값(라이브)'!$C$43 -> M400-50A (50PN400) | D14: - | E14: 라이브러리 M400-50A (없으면 50PN400 등가)
A15: Stator | B15: Number of Slots | C15: ='설계값(라이브)'!$C$46 -> 36 | D15: -
A16: Stator | B16: Slot Type | C16: 3 | D16: - | E16: 사다리꼴 + 반원 바닥
A17: Stator Slot | B17: Hs0 | C17: ='설계값(라이브)'!$C$76 -> 0.5 | D17: mm
A18: Stator Slot | B18: Hs1 | C18: ='설계값(라이브)'!$C$77 -> 1 | D18: mm
A19: Stator Slot | B19: Hs2 | C19: ='설계값(라이브)'!$C$88 -> 10.810347 | D19: mm
A20: Stator Slot | B20: Bs0 | C20: ='설계값(라이브)'!$C$78 -> 2.5 | D20: mm
A21: Stator Slot | B21: Bs1 | C21: ='설계값(라이브)'!$C$85 -> 4.8619724 | D21: mm
A22: Stator Slot | B22: Bs2 | C22: ='설계값(라이브)'!$C$86 -> 7.3939804 | D22: mm
A23: Stator Winding | B23: Winding Layers | C23: ='설계값(라이브)'!$C$50 -> 2 | D23: -
A24: Stator Winding | B24: Winding Type | C24: Whole-Coiled (Lap) | D24: -
A25: Stator Winding | B25: Parallel Branches | C25: ='설계값(라이브)'!$C$52 -> 1 | D25: -
A26: Stator Winding | B26: Conductors per Slot | C26: ='설계값(라이브)'!$C$69 -> 30 | D26: -
A27: Stator Winding | B27: Coil Pitch | C27: ='설계값(라이브)'!$C$51 -> 8 | D27: slots
A28: Stator Winding | B28: Number of Strands | C28: ='설계값(라이브)'!$C$53 -> 2 | D28: -
A29: Stator Winding | B29: Wire Diameter (bare) | C29: ='설계값(라이브)'!$C$54 -> 0.9 | D29: mm | E29: 절연 포함 ≈ 0.98
A30: Stator Winding | B30: End Length (편측, 대체) | C30: ='설계값(라이브)'!$C$100 -> 121.53096 | D30: mm | E30: 자동 생성 시 비교값
A31: Rotor | B31: Outer Diameter | C31: ='설계값(라이브)'!$C$40 -> 97.4 | D31: mm
A32: Rotor | B32: Inner Diameter (shaft) | C32: ='설계값(라이브)'!$C$44 -> 36 | D32: mm
A33: Rotor | B33: Length | C33: ='설계값(라이브)'!$C$41 -> 135 | D33: mm
A34: Rotor | B34: Number of Slots | C34: ='설계값(라이브)'!$C$48 -> 28 | D34: - | E34: ★ 스큐 설계 확정 28
A35: Rotor | B35: Slot Type | C35: 2 | D35: - | E35: 상·하 원형 배형, 반폐
A36: Rotor | B36: Skew Width | C36: ='설계값(라이브)'!$C$49 -> 1 | D36: stator slot pitch | E36: ★ 1
A37: Rotor Slot | B37: Hs0 | C37: ='설계값(라이브)'!$C$138 -> 0.5 | D37: mm | E37: 브리지
A38: Rotor Slot | B38: Hs2 | C38: ='설계값(라이브)'!$C$143 -> 15.8 | D38: mm
A39: Rotor Slot | B39: Bs0 | C39: ='설계값(라이브)'!$C$139 -> 1 | D39: mm
A40: Rotor Slot | B40: Bs1 | C40: ='설계값(라이브)'!$C$141 -> 5.4 | D40: mm
A41: Rotor Slot | B41: Bs2 | C41: ='설계값(라이브)'!$C$142 -> 2 | D41: mm
...

Sheet ITSC 케이스
A1: Maxwell ITSC 해석 케이스 — 상 턴수 비율로 정의 (턴수 가정의 영향 제거)
A3: 상당 직렬 턴수 N_ph | C3: ='설계값(라이브)'!$C$68 -> 180
A4: 코일당 턴수 N_c | C4: ='설계값(라이브)'!$C$67 -> 15
A6: 케이스 | B6: 단락 턴 수 | C6: 상 턴수 비율 | D6: 코일 기준 | E6: 단락 저항 R_f | F6: 부하 | G6: 등가모델 대응 | H6: 비고
A7: C0 정상 | B7: 0 | C7: =B7/$C$3 -> 0 | D7: - | E7: 0.1 Ω | F7: 정격 | G7: I₂/I₁ ≈ 0.006 (평형 전원) | H7: 기준선
A8: C1 초기 | B8: 4 | C8: =B8/$C$3 -> 0.022222222 | D8: 코일 1개 내 4턴 | E8: 0.1 Ω (금속 접촉) | F8: 정격 | G8: 등가모델 4턴 (0.104) | H8: 등가모델의 턴 비율로 환산해 대응
A9: C2 진행 | B9: 8 | C9: =B9/$C$3 -> 0.044444444 | D9: 코일 1개 내 8턴 | E9: 0.1 Ω | F9: 정격 | G9: -
A10: C3 심화 | B10: 12 | C10: =B10/$C$3 -> 0.066666667 | D10: 코일 1개 내 12턴 | E10: 0.1 Ω | F10: 정격 | G10: 등가모델 12턴 (0.269)
A11: C4 코일 전체 | B11: =C4 -> 15 | C11: =B11/$C$3 -> 0.083333333 | D11: 코일 1개 전체 (코일 간 절연 파괴형) | E11: 0.1 Ω | F11: 정격 | G11: - | H11: N_c 턴
A12: C5 2코일 | B12: =2*C4 -> 30 | C12: =B12/$C$3 -> 0.16666667 | D12: 인접 2코일 직렬 | E12: 0.1 Ω | F12: 정격 | G12: -
A13: C1-L 경부하 | B13: 4 | C13: =B13/$C$3 -> 0.022222222 | D13: 코일 1개 내 4턴 | E13: 0.1 Ω | F13: 50 % | G13: - | H13: 부하 의존성
A14: C1-R 저항성 | B14: 4 | C14: =B14/$C$3 -> 0.022222222 | D14: 코일 1개 내 4턴 | E14: 1.0 Ω (절연 열화 초기) | F14: 정격 | G14: - | H14: 저항 의존성
A16: 단락 턴 수가 코일당 턴수(N_c)를 넘으면 인접 코일로 확장해 정의. 스큐는 기본파 성분(I₂/I₁)에 영향 없음.

Sheet MCSA·진동 주파수
A1: 전류·진동 특징 주파수 — 설계값 링크 (Q_r·슬립 변경 시 자동 갱신)
A3: 항목 | B3: 식 | C3: 값 | D3: 단위 | E3: 용도
A4: 회전 주파수 1× | B4: n/60 | C4: ='설계값(라이브)'!$C$13/60 -> 29.333333 | D4: Hz | E4: 진동 기본
A5: 슬립 주파수 | B5: s·f | C5: ='설계값(라이브)'!$C$25*'설계값(라이브)'!$C$11 -> 1.3333333 | D5: Hz
A6: 로터 슬롯 고조파 (하측) | B6: f·[Q_r(1−s)/p − 1] | C6: ='설계값(라이브)'!$C$11*('설계값(라이브)'!$C$48*(1-'설계값(라이브)'!$C$25)/'설계값(라이브)'!$C$23-1) -> 761.33333 | D6: Hz | E6: ★ Q_r 판별
A7: 로터 슬롯 고조파 (상측) | B7: f·[Q_r(1−s)/p + 1] | C7: ='설계값(라이브)'!$C$11*('설계값(라이브)'!$C$48*(1-'설계값(라이브)'!$C$25)/'설계값(라이브)'!$C$23+1) -> 881.33333 | D7: Hz | E7: 쌍 간격 2f = 120 Hz
A8: 로터 슬롯 통과 진동 | B8: Q_r·n/60 | C8: ='설계값(라이브)'!$C$48*'설계값(라이브)'!$C$13/60 -> 821.33333 | D8: Hz | E8: 측대파 ±2f
A9: 극 통과 주파수 | B9: (n_s−n)/60·p | C9: =('설계값(라이브)'!$C$24-'설계값(라이브)'!$C$13)/60*'설계값(라이브)'!$C$12 -> 2.6666667 | D9: Hz | E9: 로터 바 결함 측대파
A10: ITSC 측대파 (참고) | B10: f·[1 ± 2k(1−s)/p] | C10: 기본파 ±(1−s)·f·2/p = 60 ± 58.7 | D10: Hz | E10: I₂/I₁ 가 주 지표
A11: 베어링 볼 수 / 볼 지름 / 피치 지름 (6206) | B11: 규격 | C11: 9 / 9.525 / 46.0 | D11: - / mm / mm | E11: 외부 규격 (SKF)
A12: BPFO | B12: N_b/2·f_r·(1−D_w/d_m) | C12: =9/2*'설계값(라이브)'!$C$13/60*(1-9.525/46) -> 104.66739 | D12: Hz | E12: 외륜 결함
A13: BPFI | B13: N_b/2·f_r·(1+D_w/d_m) | C13: =9/2*'설계값(라이브)'!$C$13/60*(1+9.525/46) -> 159.33261 | D13: Hz | E13: 내륜 결함
A14: BSF | B14: d_m/(2D_w)·f_r·(1−(D_w/d_m)²) | C14: =46/(2*9.525)*'설계값(라이브)'!$C$13/60*(1-(9.525/46)^2) -> 67.79419 | D14: Hz | E14: 볼 결함
A15: FTF | B15: f_r/2·(1−D_w/d_m) | C15: ='설계값(라이브)'!$C$13/60/2*(1-9.525/46) -> 11.62971 | D15: Hz | E15: 케이지

Sheet 권선 배치표
A1: 고정자 권선 배치 — 36슬롯 / 4극 / 3상 / 2층 중권 / 코일 피치 8 (q = 3, 상대 60°)
A2: 코일 i: 상층 = 슬롯 i, 하층 = 슬롯 i+8 (반대 극성). 상 순서 A+ C− B+ A− C+ B− (각 3슬롯). Maxwell 3D에서 각 코일이 솔리드 1개 → 코일 터미널 1개.
A4: 슬롯 | B4: 상층 (코일 i 시작) | C4: 하층 (코일 i−8 끝) | D4: 코일 번호 | E4: 코일 상 | F4: Maxwell Winding 이름 | G4: 결함 코일 지정
A5: 1 | B5: A+ | C5: A+ (코일 29) | D5: 1 | E5: A | F5: PhaseA | G5: ★ 결함 코일 (Coil_1: 슬롯 1 상층 ↔ 슬롯 9 하층)
A6: 2 | B6: A+ | C6: A+ (코일 30) | D6: 2 | E6: A | F6: PhaseA
A7: 3 | B7: A+ | C7: C- (코일 31) | D7: 3 | E7: A | F7: PhaseA
A8: 4 | B8: C- | C8: C- (코일 32) | D8: 4 | E8: C | F8: PhaseC
A9: 5 | B9: C- | C9: C- (코일 33) | D9: 5 | E9: C | F9: PhaseC
A10: 6 | B10: C- | C10: B+ (코일 34) | D10: 6 | E10: C | F10: PhaseC
A11: 7 | B11: B+ | C11: B+ (코일 35) | D11: 7 | E11: B | F11: PhaseB
A12: 8 | B12: B+ | C12: B+ (코일 36) | D12: 8 | E12: B | F12: PhaseB
A13: 9 | B13: B+ | C13: A- (코일 1) | D13: 9 | E13: B | F13: PhaseB
A14: 10 | B14: A- | C14: A- (코일 2) | D14: 10 | E14: A | F14: PhaseA
A15: 11 | B15: A- | C15: A- (코일 3) | D15: 11 | E15: A | F15: PhaseA
A16: 12 | B16: A- | C16: C+ (코일 4) | D16: 12 | E16: A | F16: PhaseA
A17: 13 | B17: C+ | C17: C+ (코일 5) | D17: 13 | E17: C | F17: PhaseC
... A40: 36 | B40: B- | C40: A+ (코일 28) | D40: 36 | E40: B | F40: PhaseB
A42: 결함 코일 모델링 (ITSC): Coil_1 솔리드를 단면적 비율 n/N_c 로 둘로 분할 → Coil_1_healthy (N_c−n 턴, PhaseA 에 직렬) / Coil_1_short (n 턴, 별도 Winding 'FaultLoop') → 외부 회로에서 FaultLoop 양단을 R_f 로 연결. 분할 비율은 「ITSC 케이스」 시트의 상 턴수 비율 × N_ph / N_c.
A43: 코일 터미널 'Number of Conductors': healthy = N_c − n, short = n. 두 터미널 전류 방향은 원래 코일과 동일.
A44: 1/4 주기 모델(90° mech)을 쓰면 슬롯 1~9 만 모델에 포함되고 Coil_1 은 그 안에 있음. 단, 결함은 주기 대칭을 깨므로 ★ ITSC 케이스는 전체 360° 모델 또는 1/2 모델(결함 코일이 양쪽에 대칭 배치되는 가정)로 풀어야 함 — 정상 케이스만 1/4 모델 허용.
A45: 병렬 회로 a = 1: 상당 12코일 전부 직렬. a 가 2 로 확인되면 Winding 을 2 가지로 분리해 재정의.

Sheet 해석 설정(3D)
A1: Maxwell 3D Transient 해석 설정 — 케이스별 속도(슬립) 표는 Kloss 식으로 라이브 계산
A3: 부하 (T/T_n) | B3: Kloss k = 2·T_max/T | C3: s/s_max | D3: 슬립 s | E3: 회전수 n (Motion 고정 속도) | F3: rpm | G3: 비고
A4: 0.25 | B4: =2*'설계값(라이브)'!$C$15/A4 -> 20 | C4: =(B4-SQRT(B4^2-4))/2 -> 0.050125629 | D4: =C4*'설계값(라이브)'!$C$181 -> 0.0053370293 | E4: ='설계값(라이브)'!$C$24*(1-D4) -> 1790.3933 | F4: =ROUND(E4,1) -> 1790.4
A5: 0.5 | B5: =2*'설계값(라이브)'!$C$15/A5 -> 10 | C5: =(B5-SQRT(B5^2-4))/2 -> 0.10102051 | D5: =C5*'설계값(라이브)'!$C$181 -> 0.010755964 | E5: ='설계값(라이브)'!$C$24*(1-D5) -> 1780.6393 | F5: =ROUND(E5,1) -> 1780.6
A6: 0.75 | B6: =2*'설계값(라이브)'!$C$15/A6 -> 6.6666667 | C6: =(B6-SQRT(B6^2-4))/2 -> 0.153536 | D6: =C6*'설계값(라이브)'!$C$181 -> 0.016347448 | E6: ='설계값(라이브)'!$C$24*(1-D6) -> 1770.5746 | F6: =ROUND(E6,1) -> 1770.6
A7: 1 | B7: =2*'설계값(라이브)'!$C$15/A7 -> 5 | C7: =(B7-SQRT(B7^2-4))/2 -> 0.20871215 | D7: =C7*'설계값(라이브)'!$C$181 -> 0.022222222 | E7: ='설계값(라이브)'!$C$24*(1-D7) -> 1760 | F7: =ROUND(E7,1) -> 1760 | G7: 정격점 검산: s = 2.22 %
A8: 1.15 | B8: =2*'설계값(라이브)'!$C$15/A8 -> 4.3478261 | C8: =(B8-SQRT(B8^2-4))/2 -> 0.24365453 | D8: =C8*'설계값(라이브)'!$C$181 -> 0.025942644 | E8: ='설계값(라이브)'!$C$24*(1-D8) -> 1753.3032 | F8: =ROUND(E8,1) -> 1753.3 | G8: SF 1.15 과부하
A11: 구분 | B11: 설정 | C11: 값 | D11: 근거 / 비고
A12: 모델 | B12: 주기 모델 | C12: 정상 케이스: 1/4 (Master/Slave 90°), Symmetry Multiplier 4 / ITSC 케이스: 전체 360° | D12: 결함은 주기 대칭을 깸
A13: 모델 | B13: 스큐 | C13: RMxprt 3D export 시 로터 바 트위스트 자동 생성 (1 슬롯피치, 3.6°) | D13: 「설계값」 §8
A14: 모델 | B14: 엔드권선 | C14: RMxprt 자동 생성 (End Length ≈ 122 mm 편측) | D14: 3D 누설 반영
A15: 재질 | B15: 고정자·로터 코어 | C15: M400-50A: B-H 곡선 + 코어손 계수(K_h, K_c, K_e) — 라이브러리에 없으면 강판사(50PN400) 데이터시트 곡선을 입력 | D15: ★ 시트에 곡선 데이터 없음 — 확보 필요
A16: 재질 | B16: 로터 바·엔드링 | C16: cast_aluminum: σ = 3.53e7 S/m @20 °C (ρ 0.0283 μΩ·m), 온도 95 °C 케이스는 σ = 2.72e7 | D16: 「설계값」 §6
A17: 재질 | B17: 고정자 권선 | C17: copper, stranded (와전류 무시), 95 °C 저항률 반영은 외부 회로 R_1 로
A18: 재질 | B18: 축 | C18: steel_1008 (자성)
A19: 여자 | B19: 전원 | C19: 외부 회로: 3상 Y 전압원 V_ph = 219.4 V (peak 310.3 V), 60 Hz, 상순 A-B-C | D19: 380 V 전용형 Δ 확인 시 변경
A20: 여자 | B20: 결함 가지 | C20: Winding 'FaultLoop' 양단에 R_f (0.1 / 1.0 Ω) + 작은 L (1 μH, 수치 안정) | D20: 「ITSC 케이스」
A21: 여자 | B21: 코일 저항 | C21: Winding Resistance = R_1 상당 (코일별 R_1/12) | D21: 「설계값」 R1
A22: Motion | B22: 방식 | C22: Band 객체, Rotation, Constant speed = 위 표의 rpm (기계 동역학 미계산) | D22: 정상상태 빨리 도달
A23: Motion | B23: 초기 위치 | C23: 0°, 전기 위상은 전압원 위상으로 정렬
A24: 메시 | B24: 공극 | C24: Band 포함 3층 (stator-side gap / band / rotor-side gap), 요소 길이 0.3 mm 이하 | D24: 토크 정확도
A25: 메시 | B25: 코어·코일·바 | C25: 코어 4 mm, 바 1.5 mm (표피효과), 코일 3 mm, 1/4 모델 약 30~40만 요소 | D25: 추정
A26: 시간 | B26: 시간 간격 | C26: 50 μs (슬롯 고조파 881 Hz 의 1/22, 전기 주기당 333 스텝)
A27: 시간 | B27: 종료 시간 | C27: 0.10 s (과도 50 ms + 저장 창 50 ms = 3 전기 주기) | D27: 속도 고정이므로 충분
A28: 시간 | B28: 필드 저장 | C28: 마지막 주기 1 ms 간격 (17 시점) — 시각화·손실 적분용
A29: 솔버 | B29: 비선형 잔차 / 반복 | C29: 0.005 / 최대 10
A30: 솔버 | B30: 손실 | C30: Core loss ON (코어), Solid loss ON (바·링), Stranded loss ON (코일)
A31: 예상 비용 | B31: 3D 1/4 정상 케이스 | C31: 2,000 스텝 × 15~40 s ≈ 8~22 h (9900X 16코어) | D31: 추정
A32: 예상 비용 | B32: 3D 전체 ITSC 케이스 | C32: × 3~4 → 1.5~3 일/케이스 → 3D 는 정상 + ITSC 2 케이스로 제한, 스윕은 2D

Sheet 출력 변수·회로
A1: 출력 변수 정의 (Isaac Sim 연동 데이터 계약) + 외부 회로 넷리스트
A3: 출력 | B3: Maxwell 정의 | C3: 저장 형식 | D3: Isaac Sim 용도
A4: 선전류 Ia, Ib, Ic | B4: Winding → Current(PhaseA/B/C) | C4: waveforms.parquet (t, A), 50 μs | D4: 전류 색 애니메이션, 대시보드 파형, I₂/I₁
A5: 단락 루프 전류 I_f | B5: Current(FaultLoop) | C5: waveforms.parquet | D5: 핫스팟 발열 세기
A6: 토크 | B6: Moving1.Torque | C6: waveforms.parquet (N·m) | D6: 토크 리플
A7: 고정자 동손 (코일별) | B7: StrandedLoss 또는 3·I²·R_coil 후처리 | C7: losses.json [W] | D7: 열 모델 권선 영역
A8: 치 철손 / 요크 철손 | B8: Fields Calculator: Integrate(Volume(StatorTeeth / StatorYoke), CoreLossDensity) → Output Variable | C8: losses.json | D8: 열 모델 코어·하우징 영역 (코어를 치/요크 객체로 분리)
A9: 바 손실 / 엔드링 손실 | B9: Integrate(Volume(Bars / EndRings), OhmicLoss) | C9: losses.json | D9: 열 모델 로터 영역
A10: 단락 루프 손실 | B10: I_f²·R_f + Integrate(Volume(Coil_1_short), OhmicLoss) | C10: losses.json | D10: 국부 핫스팟
A11: 특징량 | B11: 후처리 Python: 기본파 페이저 → I₂/I₁, 상 불평형, 3·5·7차, RSH(761/881 Hz) 진폭 | C11: features.json | D11: 판정 엔진 simulation 등급 참조값
A12: 필드 스냅샷 | B12: Export → Fields → Grid (B, J) 정규 격자 2 mm, 마지막 시점 | C12: field_B.npz / field_J.npz | D12: 모터 메시 정점 색 히트맵
A13: 검증 블록 | B13: 정격 케이스: I_rms, PF, η(= P_out/(P_out+ΣP)), T_avg | C13: validation.json | D13: 카탈로그 정합 자동 판정 (±5 % / ±0.03 / ±1.5 %p)
A14: 매니페스트 | B14: 케이스 축(부하·결함 비율·R_f·온도), 단위, 샘플링, 모델 해시, RMxprt 입력 사본 | C14: manifest.json | D14: FemSource 보간 격자 정의
A17: 외부 회로 (Maxwell Circuit Editor) 넷리스트 개요
A18: V_A: 노드 N1–GND, 310.3 V·sin(2π·60·t) V_B: N2–GND, 위상 −120° V_C: N3–GND, 위상 −240°
A19: PhaseA 권선 (Coil_1_healthy 포함 12코일 직렬): N1 – Nn (중성점) PhaseB: N2 – Nn PhaseC: N3 – Nn Nn: 중성점 (절연, GND 와 1 MΩ 로 기준 고정)
A20: FaultLoop 권선 (Coil_1_short, n 턴): 노드 F1–F2. R_f (0.1 Ω 또는 1.0 Ω) + L_f 1 μH 로 F1–F2 단락. 정상 케이스는 R_f = 1 MΩ (개방).
A21: 선 임피던스: 각 상에 R_line = 0, L_line = 0 (현장 재현 시 케이블 값 삽입). 전압 불평형 케이스: V_B 진폭 × (1 − u), u = 0.02.
A22: 권선 저항: Winding 속성 Resistance = R_1·(코일 수 분담). 95 °C 케이스는 R_1(95 °C) = 1.62 Ω, 20 °C 케이스는 ×0.773.

Sheet 현장확인 체크리스트
A1: 실물 확보 시 확인 순서 — 가정값 → 실측값 교체
A3: 순서 | B3: 확인 항목 | C3: 방법 | D3: 교체되는 시트 셀 | E3: 영향
A4: 1 | B4: 명판: 전류·결선·회전수 | C4: 명판 사진 | D4: 설계값 §1, Vph·a | E4: r 판정 I_rated 확정, Y/Δ 확정
A5: 2 | B5: 로터 바 수 Q_r | C5: 로터 축방향 사진에서 바 자국 세기 (마커 1개 표시 후 1회전) 또는 전류 RSH | D5: 설계값 Qr | E5: 슬롯 고조파 주파수·힘파 차수 — 가정 중 영향 최대
A6: 3 | B6: 로터 스큐 | C6: 로터 측면 비스듬히 사진, 양단 바 어긋남 슬롯 수 | D6: 설계값 skew | E6: 힘파·동기토크 감쇠, 3D 트위스트 각
A7: 4 | B7: 고정자 슬롯 수 Q_s | C7: 보어 슬롯 웨지 세기 | D7: 설계값 Qs | E7: 권선 배치
A8: 5 | B8: 코일당 턴수·소선 지름·병렬 회로 | C8: 코일 1개 분리 계수, 버니어, 코일군 점퍼 관찰 | D8: 설계값 Nc·dw·a | E8: ITSC 비율 분모, R_1
A9: 6 | B9: 베어링 번호 | C9: 베어링 각인 | D9: 설계값 brg | E9: BPFO/BPFI
A10: 7 | B10: 적층 길이·코어 외경 | C10: 분해 실측 | D10: 설계값 L·Dso | E10: 자속·관성 검산
